2022-06-06 23:44:26,609 ERROR: </home/stanislav/study/client_server_app/client-server-applcations/base.py> <handler.handle_request()>: 1 validation error for Request __root__ Extra data: line 1 column 128 (char 127) (type=value_error.jsondecode; msg=Extra data; doc={"action": "quit", "time": "2022-06-06T23:44:26.608469", "user": {"account_name": "stas", "password": "s", "status": "online"}}{"action": "quit", "time": "2022-06-06T23:44:26.608785", "user": {"account_name": "stas", "password": "s", "status": "online"}}; pos=127; lineno=1; colno=128)
2022-06-06 23:44:26,610 ERROR: </home/stanislav/study/client_server_app/client-server-applcations/server.py> <self.close_request()>: 'NoneType' object has no attribute 'user'
2022-06-06 23:44:26,610 ERROR: </home/stanislav/study/client_server_app/client-server-applcations/server.py> <server.serve()>: file descriptor cannot be a negative integer (-1)
2022-06-06 23:46:48,542 ERROR: </usr/lib/python3.8/threading.py> <self._target(*self._args, **self._kwargs)>: 'stas'
2022-06-06 23:46:58,990 ERROR: </usr/lib/python3.8/threading.py> <self._target(*self._args, **self._kwargs)>: 'val'
2022-06-06 23:47:06,804 ERROR: <client.py> <self.get_outbox_message(to=self.action)>: 'val'
2022-06-06 23:47:06,806 ERROR: </usr/lib/python3.8/threading.py> <self._target(*self._args, **self._kwargs)>: 'stas'
2022-06-06 23:49:00,451 ERROR: <client.py> <self.quit()>: [Errno 9] Bad file descriptor
2022-06-06 23:49:00,451 ERROR: </home/stanislav/study/client_server_app/client-server-applcations/base.py> <handler.handle_request()>: 1 validation error for Request __root__ Extra data: line 1 column 127 (char 126) (type=value_error.jsondecode; msg=Extra data; doc={"action": "quit", "time": "2022-06-06T23:49:00.450323", "user": {"account_name": "val", "password": "s", "status": "online"}}{"action": "quit", "time": "2022-06-06T23:49:00.450618", "user": {"account_name": "val", "password": "s", "status": "online"}}; pos=126; lineno=1; colno=127)
2022-06-06 23:49:00,451 ERROR: </home/stanislav/study/client_server_app/client-server-applcations/server.py> <self.close_request()>: 'NoneType' object has no attribute 'user'
2022-06-06 23:49:00,452 ERROR: </home/stanislav/study/client_server_app/client-server-applcations/server.py> <server.serve()>: file descriptor cannot be a negative integer (-1)
2022-06-06 23:49:06,410 ERROR: <client.py> <except KeyboardInterrupt:>: Not connected
2022-06-06 23:49:06,411 ERROR: <client.py> <self.quit()>: [Errno 9] Bad file descriptor
2022-06-06 23:49:20,923 ERROR: </usr/lib/python3.8/threading.py> <self._target(*self._args, **self._kwargs)>: 'val'
2022-06-06 23:49:32,563 ERROR: </usr/lib/python3.8/threading.py> <self._target(*self._args, **self._kwargs)>: 'stas'
2022-06-06 23:49:35,025 ERROR: <client.py> <self.get_outbox_message(to=self.action)>: 'stas'
2022-06-06 23:49:35,026 ERROR: </usr/lib/python3.8/threading.py> <self._target(*self._args, **self._kwargs)>: 'val'
2022-06-06 23:49:49,450 ERROR: </usr/lib/python3.8/threading.py> <self._target(*self._args, **self._kwargs)>: 'stas'
2022-06-06 23:49:52,872 ERROR: <client.py> <self.get_outbox_message(to=self.action)>: 'stas'
2022-06-06 23:50:02,026 ERROR: </usr/lib/python3.8/threading.py> <self._target(*self._args, **self._kwargs)>: ''
2022-06-06 23:50:09,937 ERROR: </usr/lib/python3.8/threading.py> <self._target(*self._args, **self._kwargs)>: 'stas'
2022-06-06 23:50:11,904 ERROR: <client.py> <self.get_outbox_message(to=self.action)>: 'stas'
2022-06-06 23:51:54,454 ERROR: <client.py> <self.quit()>: [Errno 9] Bad file descriptor
2022-06-06 23:51:54,454 ERROR: </home/stanislav/study/client_server_app/client-server-applcations/base.py> <handler.handle_request()>: 1 validation error for Request __root__ Extra data: line 1 column 127 (char 126) (type=value_error.jsondecode; msg=Extra data; doc={"action": "quit", "time": "2022-06-06T23:51:54.453971", "user": {"account_name": "val", "password": "s", "status": "online"}}{"action": "quit", "time": "2022-06-06T23:51:54.454253", "user": {"account_name": "val", "password": "s", "status": "online"}}; pos=126; lineno=1; colno=127)
2022-06-06 23:51:54,455 ERROR: </home/stanislav/study/client_server_app/client-server-applcations/server.py> <self.close_request()>: 'NoneType' object has no attribute 'user'
2022-06-06 23:51:54,455 ERROR: </home/stanislav/study/client_server_app/client-server-applcations/server.py> <server.serve()>: file descriptor cannot be a negative integer (-1)
2022-06-06 23:51:56,606 ERROR: <client.py> <except KeyboardInterrupt:>: Not connected
2022-06-06 23:51:56,607 ERROR: <client.py> <self.quit()>: [Errno 9] Bad file descriptor
2022-06-06 23:57:46,335 ERROR: </usr/lib/python3.8/threading.py> <self._target(*self._args, **self._kwargs)>: 'stas'
2022-06-06 23:57:57,015 ERROR: </usr/lib/python3.8/threading.py> <self._target(*self._args, **self._kwargs)>: 'val'
2022-06-06 23:58:02,181 ERROR: <client.py> <self.get_outbox_message(to=self.action)>: 'val'
2022-06-06 23:58:02,182 ERROR: </usr/lib/python3.8/threading.py> <self._target(*self._args, **self._kwargs)>: 'stas'
2022-06-06 23:58:18,150 ERROR: </usr/lib/python3.8/threading.py> <self._target(*self._args, **self._kwargs)>: 'val'
2022-06-06 23:58:20,492 ERROR: <client.py> <self.get_outbox_message(to=self.action)>: 'val'
2022-06-06 23:59:26,036 ERROR: <client.py> <self.quit()>: [Errno 9] Bad file descriptor
2022-06-06 23:59:26,036 ERROR: </home/stanislav/study/client_server_app/client-server-applcations/base.py> <handler.handle_request()>: 1 validation error for Request __root__ Extra data: line 1 column 128 (char 127) (type=value_error.jsondecode; msg=Extra data; doc={"action": "quit", "time": "2022-06-06T23:59:26.035486", "user": {"account_name": "stas", "password": "s", "status": "online"}}{"action": "quit", "time": "2022-06-06T23:59:26.035769", "user": {"account_name": "stas", "password": "s", "status": "online"}}; pos=127; lineno=1; colno=128)
2022-06-06 23:59:26,036 ERROR: </home/stanislav/study/client_server_app/client-server-applcations/server.py> <self.close_request()>: 'NoneType' object has no attribute 'user'
2022-06-06 23:59:26,037 ERROR: </home/stanislav/study/client_server_app/client-server-applcations/server.py> <server.serve()>: file descriptor cannot be a negative integer (-1)
2022-06-06 23:59:33,091 ERROR: <client.py> <client.request(Action.quit)>: Not connected
2022-06-06 23:59:33,093 ERROR: <client.py> <self.quit()>: [Errno 9] Bad file descriptor
2022-06-06 23:59:48,306 ERROR: <client.py> <with TCPSocketClient(host=cl_host, port=cl_port, username=username, password=password) as client:>: password is required
2022-06-06 23:59:48,308 ERROR: <client.py> <client.connect()>: 'NoneType' object has no attribute 'connect'
2022-06-06 23:59:49,802 ERROR: <client.py> <self.quit()>: 'TCPSocketClient' object has no attribute 'user'
2022-06-06 23:59:49,802 ERROR: <client.py> <main()>: 'NoneType' object has no attribute 'close'
2022-06-06 23:59:59,940 ERROR: </usr/lib/python3.8/threading.py> <self._target(*self._args, **self._kwargs)>: 'val'
2022-06-07 00:00:02,980 ERROR: </usr/lib/python3.8/threading.py> <self._target(*self._args, **self._kwargs)>: 'stas'
2022-06-07 00:00:07,114 ERROR: <client.py> <self.get_outbox_message(to=self.action)>: 'stas'
2022-06-07 00:00:07,116 ERROR: </usr/lib/python3.8/threading.py> <self._target(*self._args, **self._kwargs)>: 'val'
2022-06-07 00:00:16,059 ERROR: </usr/lib/python3.8/threading.py> <self._target(*self._args, **self._kwargs)>: 'stas'
2022-06-07 00:00:18,178 ERROR: <client.py> <self.get_outbox_message(to=self.action)>: 'stas'
2022-06-07 00:01:04,985 ERROR: <client.py> <self.quit()>: [Errno 9] Bad file descriptor
2022-06-07 00:01:04,986 ERROR: </home/stanislav/study/client_server_app/client-server-applcations/base.py> <handler.handle_request()>: 1 validation error for Request __root__ Extra data: line 1 column 127 (char 126) (type=value_error.jsondecode; msg=Extra data; doc={"action": "quit", "time": "2022-06-07T00:01:04.985239", "user": {"account_name": "val", "password": "s", "status": "online"}}{"action": "quit", "time": "2022-06-07T00:01:04.985534", "user": {"account_name": "val", "password": "s", "status": "online"}}; pos=126; lineno=1; colno=127)
2022-06-07 00:01:04,986 ERROR: </home/stanislav/study/client_server_app/client-server-applcations/server.py> <self.close_request()>: 'NoneType' object has no attribute 'user'
2022-06-07 00:01:04,986 ERROR: </home/stanislav/study/client_server_app/client-server-applcations/server.py> <server.serve()>: file descriptor cannot be a negative integer (-1)
2022-06-07 00:01:07,249 ERROR: <client.py> <except KeyboardInterrupt:>: Not connected
2022-06-07 00:01:07,250 ERROR: <client.py> <self.quit()>: [Errno 9] Bad file descriptor
2022-06-07 00:01:23,714 ERROR: </usr/lib/python3.8/threading.py> <self._target(*self._args, **self._kwargs)>: 'stas'
2022-06-07 00:01:36,586 ERROR: </usr/lib/python3.8/threading.py> <self._target(*self._args, **self._kwargs)>: 'val'
2022-06-07 00:01:42,232 ERROR: <client.py> <self.get_outbox_message(to=self.action)>: 'val'
2022-06-07 00:01:42,233 ERROR: </usr/lib/python3.8/threading.py> <self._target(*self._args, **self._kwargs)>: 'stas'
2022-06-07 00:06:19,850 ERROR: <client.py> <self.quit()>: [Errno 9] Bad file descriptor
2022-06-07 00:06:19,850 ERROR: </usr/lib/python3.8/threading.py> <self._target(*self._args, **self._kwargs)>: [Errno 104] Connection reset by peer
2022-06-07 00:06:47,723 ERROR: </usr/lib/python3.8/threading.py> <self._target(*self._args, **self._kwargs)>: 'stas'
2022-06-07 00:06:55,050 ERROR: <client.py> <self.quit()>: [Errno 9] Bad file descriptor
2022-06-07 00:06:55,050 ERROR: </usr/lib/python3.8/threading.py> <self._target(*self._args, **self._kwargs)>: [Errno 104] Connection reset by peer
2022-06-07 00:07:08,058 ERROR: </usr/lib/python3.8/threading.py> <self._target(*self._args, **self._kwargs)>: 'val'
2022-06-07 00:07:16,432 ERROR: <client.py> <self.get_outbox_message(to=self.action)>: 'val'
2022-06-07 00:07:16,434 ERROR: </usr/lib/python3.8/threading.py> <self._target(*self._args, **self._kwargs)>: 'stas'
2022-06-07 00:07:40,632 ERROR: <client.py> <self.quit()>: [Errno 9] Bad file descriptor
