2022-06-06 22:51:42,532 ERROR: </home/stanislav/study/client_server_app/client-server-applcations/server.py> <server.serve()>: file descriptor cannot be a negative integer (-1)
2022-06-06 22:54:59,671 ERROR: <client.py> <client.run()>: threads can only be started once
2022-06-06 22:54:59,671 ERROR: </usr/lib/python3.8/threading.py> <self._target(*self._args, **self._kwargs)>: 'stas'
2022-06-06 22:57:36,660 ERROR: <client.py> <#         break>: threads can only be started once
2022-06-06 22:57:36,660 ERROR: </usr/lib/python3.8/threading.py> <self._target(*self._args, **self._kwargs)>: 'stas'
2022-06-06 22:57:38,446 ERROR: </home/stanislav/study/client_server_app/client-server-applcations/server.py> <self.close_request()>: 'NoneType' object has no attribute 'user'
2022-06-06 22:57:38,446 ERROR: </home/stanislav/study/client_server_app/client-server-applcations/server.py> <server.serve()>: file descriptor cannot be a negative integer (-1)
2022-06-06 22:57:43,181 ERROR: <client.py> <except KeyboardInterrupt:>: Not connected
2022-06-06 22:57:50,607 ERROR: <client.py> <client.connect()>: [Errno 111] Connection refused
2022-06-06 22:58:18,995 ERROR: </usr/lib/python3.8/threading.py> <self._target(*self._args, **self._kwargs)>: print_message_to_chat() got an unexpected keyword argument 'to'
2022-06-06 22:58:18,995 ERROR: <client.py> <client.run()>: threads can only be started once
2022-06-06 23:01:27,496 ERROR: </usr/lib/python3.8/threading.py> <self._target(*self._args, **self._kwargs)>: 'val'
2022-06-06 23:01:27,496 ERROR: <client.py> <client.run()>: threads can only be started once
2022-06-06 23:04:32,614 ERROR: </home/stanislav/study/client_server_app/client-server-applcations/server.py> <self.close_request()>: 'NoneType' object has no attribute 'user'
2022-06-06 23:04:32,614 ERROR: </home/stanislav/study/client_server_app/client-server-applcations/server.py> <server.serve()>: file descriptor cannot be a negative integer (-1)
2022-06-06 23:07:06,708 ERROR: <client.py> <client.connect()>: [Errno 111] Connection refused
2022-06-06 23:07:23,592 ERROR: </usr/lib/python3.8/threading.py> <self._target(*self._args, **self._kwargs)>: 'valval'
2022-06-06 23:07:23,592 ERROR: <client.py> <client.run()>: threads can only be started once
2022-06-06 23:07:53,527 ERROR: </usr/lib/python3.8/threading.py> <self._target(*self._args, **self._kwargs)>: 'valval'
2022-06-06 23:07:53,528 ERROR: <client.py> <result = self.send_request(request.json(exclude_none=True, ensure_ascii=False).encode(DEFAULT_ENCODING))>: [Errno 9] Bad file descriptor
2022-06-06 23:08:00,192 ERROR: </home/stanislav/study/client_server_app/client-server-applcations/server.py> <self.close_request()>: 'NoneType' object has no attribute 'user'
2022-06-06 23:08:00,192 ERROR: </home/stanislav/study/client_server_app/client-server-applcations/server.py> <server.serve()>: file descriptor cannot be a negative integer (-1)
2022-06-06 23:13:03,528 ERROR: </usr/lib/python3.8/threading.py> <self._target(*self._args, **self._kwargs)>: 'stas'
2022-06-06 23:13:11,928 ERROR: </usr/lib/python3.8/threading.py> <self._target(*self._args, **self._kwargs)>: 'stas'
2022-06-06 23:13:11,930 ERROR: </usr/lib/python3.8/threading.py> <self._target(*self._args, **self._kwargs)>: 'val'
2022-06-06 23:13:17,880 ERROR: </usr/lib/python3.8/threading.py> <self._target(*self._args, **self._kwargs)>: 'dsasd'
2022-06-06 23:13:39,528 ERROR: </usr/lib/python3.8/threading.py> <self._target(*self._args, **self._kwargs)>: ''
2022-06-06 23:13:41,168 ERROR: </usr/lib/python3.8/threading.py> <self._target(*self._args, **self._kwargs)>: ''
2022-06-06 23:13:43,872 ERROR: </usr/lib/python3.8/threading.py> <self._target(*self._args, **self._kwargs)>: 'sda'
2022-06-06 23:13:45,736 ERROR: </usr/lib/python3.8/threading.py> <self._target(*self._args, **self._kwargs)>: 'asdas'
2022-06-06 23:18:03,322 ERROR: </usr/lib/python3.8/threading.py> <self._target(*self._args, **self._kwargs)>: 'asdas'
2022-06-06 23:18:03,323 ERROR: </home/stanislav/study/client_server_app/client-server-applcations/base.py> <handler.handle_request()>: 'NoneType' object has no attribute 'sock'
2022-06-06 23:18:06,513 ERROR: </home/stanislav/study/client_server_app/client-server-applcations/server.py> <self.close_request()>: 'NoneType' object has no attribute 'user'
2022-06-06 23:18:06,514 ERROR: </home/stanislav/study/client_server_app/client-server-applcations/server.py> <server.serve()>: file descriptor cannot be a negative integer (-1)
2022-06-06 23:19:10,777 ERROR: <client.py> <client.request(Action.quit)>: Not connected
2022-06-06 23:19:10,778 ERROR: <client.py> <self.quit()>: [Errno 9] Bad file descriptor
2022-06-06 23:23:27,057 ERROR: </home/stanislav/study/client_server_app/client-server-applcations/server.py> <server.serve()>: local variable 'write' referenced before assignment
2022-06-06 23:26:18,584 ERROR: </usr/lib/python3.8/threading.py> <self._target(*self._args, **self._kwargs)>: 'stas'
2022-06-06 23:26:22,879 ERROR: </usr/lib/python3.8/threading.py> <self._target(*self._args, **self._kwargs)>: 'stas'
2022-06-06 23:26:22,881 ERROR: </usr/lib/python3.8/threading.py> <self._target(*self._args, **self._kwargs)>: 'val'
2022-06-06 23:26:45,607 ERROR: </usr/lib/python3.8/threading.py> <self._target(*self._args, **self._kwargs)>: 'val'
2022-06-06 23:27:00,743 ERROR: </usr/lib/python3.8/threading.py> <self._target(*self._args, **self._kwargs)>: 'hi'
2022-06-06 23:27:07,902 ERROR: </usr/lib/python3.8/threading.py> <self._target(*self._args, **self._kwargs)>: 'hi'
2022-06-06 23:27:07,903 ERROR: </home/stanislav/study/client_server_app/client-server-applcations/base.py> <handler.handle_request()>: 'NoneType' object has no attribute 'sock'
2022-06-06 23:27:13,566 ERROR: </usr/lib/python3.8/threading.py> <self._target(*self._args, **self._kwargs)>: 'val'
2022-06-06 23:27:13,567 ERROR: </usr/lib/python3.8/threading.py> <self._target(*self._args, **self._kwargs)>: 'stas'
2022-06-06 23:27:54,990 ERROR: <client.py> <self.quit()>: [Errno 9] Bad file descriptor
2022-06-06 23:27:56,614 ERROR: <client.py> <self.quit()>: [Errno 9] Bad file descriptor
2022-06-06 23:27:56,614 ERROR: </usr/lib/python3.8/threading.py> <self._target(*self._args, **self._kwargs)>: [Errno 104] Connection reset by peer
2022-06-06 23:30:34,330 ERROR: </usr/lib/python3.8/threading.py> <self._target(*self._args, **self._kwargs)>: 'stas'
2022-06-06 23:30:49,058 ERROR: </usr/lib/python3.8/threading.py> <self._target(*self._args, **self._kwargs)>: 'val'
2022-06-06 23:30:52,578 ERROR: </usr/lib/python3.8/threading.py> <self._target(*self._args, **self._kwargs)>: 'hi'
2022-06-06 23:30:58,697 ERROR: </usr/lib/python3.8/threading.py> <self._target(*self._args, **self._kwargs)>: 'hi'
2022-06-06 23:34:51,070 ERROR: </usr/lib/python3.8/threading.py> <self._target(*self._args, **self._kwargs)>: 'stas'
2022-06-06 23:35:02,214 ERROR: </usr/lib/python3.8/threading.py> <self._target(*self._args, **self._kwargs)>: 'val'
2022-06-06 23:35:04,524 ERROR: <client.py> <self.get_outbox_message(to=self.action)>: 'val'
2022-06-06 23:35:04,526 ERROR: </usr/lib/python3.8/threading.py> <self._target(*self._args, **self._kwargs)>: 'stas'
2022-06-06 23:36:57,243 ERROR: </usr/lib/python3.8/threading.py> <self._target(*self._args, **self._kwargs)>: 'val'
2022-06-06 23:37:00,074 ERROR: <client.py> <self.get_outbox_message(to=self.action)>: 'val'
2022-06-06 23:38:24,368 ERROR: <client.py> <self.quit()>: [Errno 9] Bad file descriptor
2022-06-06 23:38:24,369 ERROR: </home/stanislav/study/client_server_app/client-server-applcations/base.py> <handler.handle_request()>: 1 validation error for Request __root__ Extra data: line 1 column 127 (char 126) (type=value_error.jsondecode; msg=Extra data; doc={"action": "quit", "time": "2022-06-06T23:38:24.368248", "user": {"account_name": "val", "password": "s", "status": "online"}}{"action": "quit", "time": "2022-06-06T23:38:24.368588", "user": {"account_name": "val", "password": "s", "status": "online"}}; pos=126; lineno=1; colno=127)
2022-06-06 23:38:24,369 ERROR: </home/stanislav/study/client_server_app/client-server-applcations/server.py> <self.close_request()>: 'NoneType' object has no attribute 'user'
2022-06-06 23:38:24,369 ERROR: </home/stanislav/study/client_server_app/client-server-applcations/server.py> <server.serve()>: file descriptor cannot be a negative integer (-1)
2022-06-06 23:38:25,664 ERROR: <client.py> <client.request(Action.quit)>: Not connected
2022-06-06 23:38:25,664 ERROR: <client.py> <self.quit()>: [Errno 9] Bad file descriptor
2022-06-06 23:42:30,068 ERROR: </usr/lib/python3.8/threading.py> <self._target(*self._args, **self._kwargs)>: 'stas'
2022-06-06 23:42:41,484 ERROR: </usr/lib/python3.8/threading.py> <self._target(*self._args, **self._kwargs)>: 'val'
2022-06-06 23:42:43,530 ERROR: <client.py> <self.get_outbox_message(to=self.action)>: 'val'
2022-06-06 23:42:43,532 ERROR: </usr/lib/python3.8/threading.py> <self._target(*self._args, **self._kwargs)>: 'stas'
2022-06-06 23:42:47,067 ERROR: <client.py> <self.quit()>: [Errno 9] Bad file descriptor
2022-06-06 23:42:47,067 ERROR: </usr/lib/python3.8/threading.py> <self._target(*self._args, **self._kwargs)>: [Errno 104] Connection reset by peer
2022-06-06 23:42:49,171 ERROR: <client.py> <self.quit()>: [Errno 9] Bad file descriptor
2022-06-06 23:43:54,195 ERROR: </usr/lib/python3.8/threading.py> <self._target(*self._args, **self._kwargs)>: 'stas'
2022-06-06 23:44:07,138 ERROR: </usr/lib/python3.8/threading.py> <self._target(*self._args, **self._kwargs)>: 'val'
2022-06-06 23:44:09,992 ERROR: <client.py> <self.get_outbox_message(to=self.action)>: 'val'
2022-06-06 23:44:09,994 ERROR: </usr/lib/python3.8/threading.py> <self._target(*self._args, **self._kwargs)>: 'stas'
2022-06-06 23:44:26,609 ERROR: <client.py> <self.quit()>: [Errno 9] Bad file descriptor
2022-06-06 23:44:27,392 ERROR: <client.py> <client.request(Action.quit)>: Not connected
2022-06-06 23:44:27,393 ERROR: <client.py> <self.quit()>: [Errno 9] Bad file descriptor
